Workbook

Sheet Dashboard
B2: DEBT PAYOFF TRACKER
B4: Your complete roadmap to becoming debt-free
B6: TOTAL DEBT REMAINING | D6: TOTAL PAID OFF | F6: MONTHLY PAYMENT AMOUNT
B7: =SUM(D14:D28) -> 46400 | D7: =SUM(C14:C28)-SUM(D14:D28) -> 4900 | F7: =SUM(F14:F28) -> 845
B9: AVG INTEREST RATE | D9: ACTIVE DEBTS | F9: PROGRESS TOWARD DEBT-FREE
B10: =IFERROR(SUMPRODUCT(D14:D28,E14:E28)/SUM(D14:D28),0) -> 0.08012306 | D10: =COUNTIF(G14:G28,"Active") -> 4 | F10: =IFERROR((SUM(C14:C28)-SUM(D14:D28))/SUM(C14:C28),0) -> 0.095516569
B12: DEBT OVERVIEW
B13: Debt Name | C13: Original Balance | D13: Current Balance | E13: Interest Rate (APR) | F13: Min Monthly Payment | G13: Status
B14: Credit Card A | C14: 5200 | D14: 4800 | E14: 0.1999 | F14: 130 | G14: Active
B15: Student Loan | C15: 28000 | D15: 26500 | E15: 0.055 | F15: 280 | G15: Active
B16: Car Loan | C16: 15000 | D16: 12000 | E16: 0.049 | F16: 350 | G16: Active
B17: Credit Card B | C17: 3100 | D17: 3100 | E17: 0.2299 | F17: 85 | G17: Active
B29: TOTALS | C29: =SUM(C14:C28) -> 51300 | D29: =SUM(D14:D28) -> 46400 | F29: =SUM(F14:F28) -> 845
B31: PAYOFF PROGRESS SUMMARY
B32: Total Original Debt | E32: =SUM(C14:C28) -> 51300
B33: Total Currently Owed | E33: =SUM(D14:D28) -> 46400
B34: Amount Paid Off | E34: =SUM(C14:C28)-SUM(D14:D28) -> 4900
B35: Percentage Complete | E35: =IFERROR((SUM(C14:C28)-SUM(D14:D28))/SUM(C14:C28),0) -> 0.095516569

Sheet Snowball Method
B2: DEBT SNOWBALL METHOD
B5: The Debt Snowball Method: Pay minimum payments on ALL debts, then throw every extra dollar at the SMALLEST BALANCE first. When that debt is paid off, roll its entire payment into the next smallest debt. This creates a "snowball" effect where your payments get larger and larger as each debt is eliminated.
B9: Extra Monthly Payment: | E9: 200 | F9: (Enter debts on Dashboard tab. This tab auto-calculates from that data.)
B11: SNOWBALL PAYOFF ORDER (Smallest Balance First)
B12: Priority | C12: Debt Name | D12: Balance | E12: APR | F12: Min Payment | G12: Extra Payment | H12: Total Payment | I12: Months to Payoff | J12: Est. Payoff Date | K12: Total Interest
B13: 1 | C13: {=IFERROR(INDEX(Dashboard!B$14:B$28,MATCH(SMALL(IF(Dashboard!D$14:D$28>0,Dashboard!D$14:D$28,1E+99),1),Dashboard!D$14:D$28,0)),"")} -> Credit Card B | D13: {=IFERROR(SMALL(IF(Dashboard!D$14:D$28>0,Dashboard!D$14:D$28),1),"")} -> 3100 | E13: {=IFERROR(INDEX(Dashboard!E$14:E$28,MATCH(SMALL(IF(Dashboard!D$14:D$28>0,Dashboard!D$14:D$28,1E+99),1),Dashboard!D$14:D$28,0)),"")} -> 0.2299 | F13: {=IFERROR(INDEX(Dashboard!F$14:F$28,MATCH(SMALL(IF(Dashboard!D$14:D$28>0,Dashboard!D$14:D$28,1E+99),1),Dashboard!D$14:D$28,0)),"")} -> 85 | G13: =$E$9 -> 200 | H13: =IFERROR(IF(D13="","",F13+G13),"") -> 285 | I13: =IFERROR(IF(D13="","",IF(E13=0,D13/H13,NPER(E13/12,-H13,D13))),"") -> 12.314039 | J13: =IFERROR(IF(D13="","",DATE(YEAR(TODAY()),MONTH(TODAY())+I13,DAY(TODAY()))),"") -> 46441 | K13: =IFERROR(IF(D13="","",(H13*I13)-D13),"") -> 409.50101
B14: 2 | C14: {=IFERROR(INDEX(Dashboard!B$14:B$28,MATCH(SMALL(IF(Dashboard!D$14:D$28>0,Dashboard!D$14:D$28,1E+99),2),Dashboard!D$14:D$28,0)),"")} -> Credit Card A | D14: {=IFERROR(SMALL(IF(Dashboard!D$14:D$28>0,Dashboard!D$14:D$28),2),"")} -> 4800 | E14: {=IFERROR(INDEX(Dashboard!E$14:E$28,MATCH(SMALL(IF(Dashboard!D$14:D$28>0,Dashboard!D$14:D$28,1E+99),2),Dashboard!D$14:D$28,0)),"")} -> 0.1999 | F14: {=IFERROR(INDEX(Dashboard!F$14:F$28,MATCH(SMALL(IF(Dashboard!D$14:D$28>0,Dashboard!D$14:D$28,1E+99),2),Dashboard!D$14:D$28,0)),"")} -> 130 | G14: =IFERROR(IF(D14="","",SUM(H13:H13)-SUM(F13:F13)+$E$9),"") -> 400 | H14: =IFERROR(IF(D14="","",F14+G14),"") -> 530 | I14: =IFERROR(IF(D14="","",IF(E14=0,D14/H14,NPER(E14/12,-H14,D14))),"") -> 9.8988861 | J14: =IFERROR(IF(D14="","",DATE(YEAR(TODAY()),MONTH(TODAY())+I14,DAY(TODAY()))),"") -> 46349 | K14: =IFERROR(IF(D14="","",(H14*I14)-D14),"") -> 446.40964
B15: 3 | C15: {=IFERROR(INDEX(Dashboard!B$14:B$28,MATCH(SMALL(IF(Dashboard!D$14:D$28>0,Dashboard!D$14:D$28,1E+99),3),Dashboard!D$14:D$28,0)),"")} -> Car Loan | D15: {=IFERROR(SMALL(IF(Dashboard!D$14:D$28>0,Dashboard!D$14:D$28),3),"")} -> 12000 | E15: {=IFERROR(INDEX(Dashboard!E$14:E$28,MATCH(SMALL(IF(Dashboard!D$14:D$28>0,Dashboard!D$14:D$28,1E+99),3),Dashboard!D$14:D$28,0)),"")} -> 0.049 | F15: {=IFERROR(INDEX(Dashboard!F$14:F$28,MATCH(SMALL(IF(Dashboard!D$14:D$28>0,Dashboard!D$14:D$28,1E+99),3),Dashboard!D$14:D$28,0)),"")} -> 350 | G15: =IFERROR(IF(D15="","",SUM(H13:H14)-SUM(F13:F14)+$E$9),"") -> 800 | H15: =IFERROR(IF(D15="","",F15+G15),"") -> 1150 | I15: =IFERROR(IF(D15="","",IF(E15=0,D15/H15,NPER(E15/12,-H15,D15))),"") -> 10.685369 | J15: =IFERROR(IF(D15="","",DATE(YEAR(TODAY()),MONTH(TODAY())+I15,DAY(TODAY()))),"") -> 46379 | K15: =IFERROR(IF(D15="","",(H15*I15)-D15),"") -> 288.17472
B16: 4 | C16: {=IFERROR(INDEX(Dashboard!B$14:B$28,MATCH(SMALL(IF(Dashboard!D$14:D$28>0,Dashboard!D$14:D$28,1E+99),4),Dashboard!D$14:D$28,0)),"")} -> Student Loan | D16: {=IFERROR(SMALL(IF(Dashboard!D$14:D$28>0,Dashboard!D$14:D$28),4),"")} -> 26500 | E16: {=IFERROR(INDEX(Dashboard!E$14:E$28,MATCH(SMALL(IF(Dashboard!D$14:D$28>0,Dashboard!D$14:D$28,1E+99),4),Dashboard!D$14:D$28,0)),"")} -> 0.055 | F16: {=IFERROR(INDEX(Dashboard!F$14:F$28,MATCH(SMALL(IF(Dashboard!D$14:D$28>0,Dashboard!D$14:D$28,1E+99),4),Dashboard!D$14:D$28,0)),"")} -> 280 | G16: =IFERROR(IF(D16="","",SUM(H13:H15)-SUM(F13:F15)+$E$9),"") -> 1600 | H16: =IFERROR(IF(D16="","",F16+G16),"") -> 1880 | I16: =IFERROR(IF(D16="","",IF(E16=0,D16/H16,NPER(E16/12,-H16,D16))),"") -> 14.605057 | J16: =IFERROR(IF(D16="","",DATE(YEAR(TODAY()),MONTH(TODAY())+I16,DAY(TODAY()))),"") -> 46500 | K16: =IFERROR(IF(D16="","",(H16*I16)-D16),"") -> 957.50792
B17: 5 | C17: {=IFERROR(INDEX(Dashboard!B$14:B$28,MATCH(SMALL(IF(Dashboard!D$14:D$28>0,Dashboard!D$14:D$28,1E+99),5),Dashboard!D$14:D$28,0)),"")} | D17: {=IFERROR(SMALL(IF(Dashboard!D$14:D$28>0,Dashboard!D$14:D$28),5),"")} | E17: {=IFERROR(INDEX(Dashboard!E$14:E$28,MATCH(SMALL(IF(Dashboard!D$14:D$28>0,Dashboard!D$14:D$28,1E+99),5),Dashboard!D$14:D$28,0)),"")} | F17: {=IFERROR(INDEX(Dashboard!F$14:F$28,MATCH(SMALL(IF(Dashboard!D$14:D$28>0,Dashboard!D$14:D$28,1E+99),5),Dashboard!D$14:D$28,0)),"")} | G17: =IFERROR(IF(D17="","",SUM(H13:H16)-SUM(F13:F16)+$E$9),"") | H17: =IFERROR(IF(D17="","",F17+G17),"") | I17: =IFERROR(IF(D17="","",IF(E17=0,D17/H17,NPER(E17/12,-H17,D17))),"") | J17: =IFERROR(IF(D17="","",DATE(YEAR(TODAY()),MONTH(TODAY())+I17,DAY(TODAY()))),"") | K17: =IFERROR(IF(D17="","",(H17*I17)-D17),"")
B18: 6 | C18: {=IFERROR(INDEX(Dashboard!B$14:B$28,MATCH(SMALL(IF(Dashboard!D$14:D$28>0,Dashboard!D$14:D$28,1E+99),6),Dashboard!D$14:D$28,0)),"")} | D18: {=IFERROR(SMALL(IF(Dashboard!D$14:D$28>0,Dashboard!D$14:D$28),6),"")} | E18: {=IFERROR(INDEX(Dashboard!E$14:E$28,MATCH(SMALL(IF(Dashboard!D$14:D$28>0,Dashboard!D$14:D$28,1E+99),6),Dashboard!D$14:D$28,0)),"")} | F18: {=IFERROR(INDEX(Dashboard!F$14:F$28,MATCH(SMALL(IF(Dashboard!D$14:D$28>0,Dashboard!D$14:D$28,1E+99),6),Dashboard!D$14:D$28,0)),"")} | G18: =IFERROR(IF(D18="","",SUM(H13:H17)-SUM(F13:F17)+$E$9),"") | H18: =IFERROR(IF(D18="","",F18+G18),"") | I18: =IFERROR(IF(D18="","",IF(E18=0,D18/H18,NPER(E18/12,-H18,D18))),"") | J18: =IFERROR(IF(D18="","",DATE(YEAR(TODAY()),MONTH(TODAY())+I18,DAY(TODAY()))),"") | K18: =IFERROR(IF(D18="","",(H18*I18)-D18),"")
B19: 7 | C19: {=IFERROR(INDEX(Dashboard!B$14:B$28,MATCH(SMALL(IF(Dashboard!D$14:D$28>0,Dashboard!D$14:D$28,1E+99),7),Dashboard!D$14:D$28,0)),"")} | D19: {=IFERROR(SMALL(IF(Dashboard!D$14:D$28>0,Dashboard!D$14:D$28),7),"")} | E19: {=IFERROR(INDEX(Dashboard!E$14:E$28,MATCH(SMALL(IF(Dashboard!D$14:D$28>0,Dashboard!D$14:D$28,1E+99),7),Dashboard!D$14:D$28,0)),"")} | F19: {=IFERROR(INDEX(Dashboard!F$14:F$28,MATCH(SMALL(IF(Dashboard!D$14:D$28>0,Dashboard!D$14:D$28,1E+99),7),Dashboard!D$14:D$28,0)),"")} | G19: =IFERROR(IF(D19="","",SUM(H13:H18)-SUM(F13:F18)+$E$9),"") | H19: =IFERROR(IF(D19="","",F19+G19),"") | I19: =IFERROR(IF(D19="","",IF(E19=0,D19/H19,NPER(E19/12,-H19,D19))),"") | J19: =IFERROR(IF(D19="","",DATE(YEAR(TODAY()),MONTH(TODAY())+I19,DAY(TODAY()))),"") | K19: =IFERROR(IF(D19="","",(H19*I19)-D19),"")
B20: 8 | C20: {=IFERROR(INDEX(Dashboard!B$14:B$28,MATCH(SMALL(IF(Dashboard!D$14:D$28>0,Dashboard!D$14:D$28,1E+99),8),Dashboard!D$14:D$28,0)),"")} | D20: {=IFERROR(SMALL(IF(Dashboard!D$14:D$28>0,Dashboard!D$14:D$28),8),"")} | E20: {=IFERROR(INDEX(Dashboard!E$14:E$28,MATCH(SMALL(IF(Dashboard!D$14:D$28>0,Dashboard!D$14:D$28,1E+99),8),Dashboard!D$14:D$28,0)),"")} | F20: {=IFERROR(INDEX(Dashboard!F$14:F$28,MATCH(SMALL(IF(Dashboard!D$14:D$28>0,Dashboard!D$14:D$28,1E+99),8),Dashboard!D$14:D$28,0)),"")} | G20: =IFERROR(IF(D20="","",SUM(H13:H19)-SUM(F13:F19)+$E$9),"") | H20: =IFERROR(IF(D20="","",F20+G20),"") | I20: =IFERROR(IF(D20="","",IF(E20=0,D20/H20,NPER(E20/12,-H20,D20))),"") | J20: =IFERROR(IF(D20="","",DATE(YEAR(TODAY()),MONTH(TODAY())+I20,DAY(TODAY()))),"") | K20: =IFERROR(IF(D20="","",(H20*I20)-D20),"")
B21: 9 | C21: {=IFERROR(INDEX(Dashboard!B$14:B$28,MATCH(SMALL(IF(Dashboard!D$14:D$28>0,Dashboard!D$14:D$28,1E+99),9),Dashboard!D$14:D$28,0)),"")} | D21: {=IFERROR(SMALL(IF(Dashboard!D$14:D$28>0,Dashboard!D$14:D$28),9),"")} | E21: {=IFERROR(INDEX(Dashboard!E$14:E$28,MATCH(SMALL(IF(Dashboard!D$14:D$28>0,Dashboard!D$14:D$28,1E+99),9),Dashboard!D$14:D$28,0)),"")} | F21: {=IFERROR(INDEX(Dashboard!F$14:F$28,MATCH(SMALL(IF(Dashboard!D$14:D$28>0,Dashboard!D$14:D$28,1E+99),9),Dashboard!D$14:D$28,0)),"")} | G21: =IFERROR(IF(D21="","",SUM(H13:H20)-SUM(F13:F20)+$E$9),"") | H21: =IFERROR(IF(D21="","",F21+G21),"") | I21: =IFERROR(IF(D21="","",IF(E21=0,D21/H21,NPER(E21/12,-H21,D21))),"") | J21: =IFERROR(IF(D21="","",DATE(YEAR(TODAY()),MONTH(TODAY())+I21,DAY(TODAY()))),"") | K21: =IFERROR(IF(D21="","",(H21*I21)-D21),"")
B22: 10 | C22: {=IFERROR(INDEX(Dashboard!B$14:B$28,MATCH(SMALL(IF(Dashboard!D$14:D$28>0,Dashboard!D$14:D$28,1E+99),10),Dashboard!D$14:D$28,0)),"")} | D22: {=IFERROR(SMALL(IF(Dashboard!D$14:D$28>0,Dashboard!D$14:D$28),10),"")} | E22: {=IFERROR(INDEX(Dashboard!E$14:E$28,MATCH(SMALL(IF(Dashboard!D$14:D$28>0,Dashboard!D$14:D$28,1E+99),10),Dashboard!D$14:D$28,0)),"")} | F22: {=IFERROR(INDEX(Dashboard!F$14:F$28,MATCH(SMALL(IF(Dashboard!D$14:D$28>0,Dashboard!D$14:D$28,1E+99),10),Dashboard!D$14:D$28,0)),"")} | G22: =IFERROR(IF(D22="","",SUM(H13:H21)-SUM(F13:F21)+$E$9),"") | H22: =IFERROR(IF(D22="","",F22+G22),"") | I22: =IFERROR(IF(D22="","",IF(E22=0,D22/H22,NPER(E22/12,-H22,D22))),"") | J22: =IFERROR(IF(D22="","",DATE(YEAR(TODAY()),MONTH(TODAY())+I22,DAY(TODAY()))),"") | K22: =IFERROR(IF(D22="","",(H22*I22)-D22),"")
B23: 11 | C23: {=IFERROR(INDEX(Dashboard!B$14:B$28,MATCH(SMALL(IF(Dashboard!D$14:D$28>0,Dashboard!D$14:D$28,1E+99),11),Dashboard!D$14:D$28,0)),"")} | D23: {=IFERROR(SMALL(IF(Dashboard!D$14:D$28>0,Dashboard!D$14:D$28),11),"")} | E23: {=IFERROR(INDEX(Dashboard!E$14:E$28,MATCH(SMALL(IF(Dashboard!D$14:D$28>0,Dashboard!D$14:D$28,1E+99),11),Dashboard!D$14:D$28,0)),"")} | F23: {=IFERROR(INDEX(Dashboard!F$14:F$28,MATCH(SMALL(IF(Dashboard!D$14:D$28>0,Dashboard!D$14:D$28,1E+99),11),Dashboard!D$14:D$28,0)),"")} | G23: =IFERROR(IF(D23="","",SUM(H13:H22)-SUM(F13:F22)+$E$9),"") | H23: =IFERROR(IF(D23="","",F23+G23),"") | I23: =IFERROR(IF(D23="","",IF(E23=0,D23/H23,NPER(E23/12,-H23,D23))),"") | J23: =IFERROR(IF(D23="","",DATE(YEAR(TODAY()),MONTH(TODAY())+I23,DAY(TODAY()))),"") | K23: =IFERROR(IF(D23="","",(H23*I23)-D23),"")
B24: 12 | C24: {=IFERROR(INDEX(Dashboard!B$14:B$28,MATCH(SMALL(IF(Dashboard!D$14:D$28>0,Dashboard!D$14:D$28,1E+99),12),Dashboard!D$14:D$28,0)),"")} | D24: {=IFERROR(SMALL(IF(Dashboard!D$14:D$28>0,Dashboard!D$14:D$28),12),"")} | E24: {=IFERROR(INDEX(Dashboard!E$14:E$28,MATCH(SMALL(IF(Dashboard!D$14:D$28>0,Dashboard!D$14:D$28,1E+99),12),Dashboard!D$14:D$28,0)),"")} | F24: {=IFERROR(INDEX(Dashboard!F$14:F$28,MATCH(SMALL(IF(Dashboard!D$14:D$28>0,Dashboard!D$14:D$28,1E+99),12),Dashboard!D$14:D$28,0)),"")} | G24: =IFERROR(IF(D24="","",SUM(H13:H23)-SUM(F13:F23)+$E$9),"") | H24: =IFERROR(IF(D24="","",F24+G24),"") | I24: =IFERROR(IF(D24="","",IF(E24=0,D24/H24,NPER(E24/12,-H24,D24))),"") | J24: =IFERROR(IF(D24="","",DATE(YEAR(TODAY()),MONTH(TODAY())+I24,DAY(TODAY()))),"") | K24: =IFERROR(IF(D24="","",(H24*I24)-D24),"")
B25: 13 | C25: {=IFERROR(INDEX(Dashboard!B$14:B$28,MATCH(SMALL(IF(Dashboard!D$14:D$28>0,Dashboard!D$14:D$28,1E+99),13),Dashboard!D$14:D$28,0)),"")} | D25: {=IFERROR(SMALL(IF(Dashboard!D$14:D$28>0,Dashboard!D$14:D$28),13),"")} | E25: {=IFERROR(INDEX(Dashboard!E$14:E$28,MATCH(SMALL(IF(Dashboard!D$14:D$28>0,Dashboard!D$14:D$28,1E+99),13),Dashboard!D$14:D$28,0)),"")} | F25: {=IFERROR(INDEX(Dashboard!F$14:F$28,MATCH(SMALL(IF(Dashboard!D$14:D$28>0,Dashboard!D$14:D$28,1E+99),13),Dashboard!D$14:D$28,0)),"")} | G25: =IFERROR(IF(D25="","",SUM(H13:H24)-SUM(F13:F24)+$E$9),"") | H25: =IFERROR(IF(D25="","",F25+G25),"") | I25: =IFERROR(IF(D25="","",IF(E25=0,D25/H25,NPER(E25/12,-H25,D25))),"") | J25: =IFERROR(IF(D25="","",DATE(YEAR(TODAY()),MONTH(TODAY())+I25,DAY(TODAY()))),"") | K25: =IFERROR(IF(D25="","",(H25*I25)-D25),"")
B26: 14 | C26: {=IFERROR(INDEX(Dashboard!B$14:B$28,MATCH(SMALL(IF(Dashboard!D$14:D$28>0,Dashboard!D$14:D$28,1E+99),14),Dashboard!D$14:D$28,0)),"")} | D26: {=IFERROR(SMALL(IF(Dashboard!D$14:D$28>0,Dashboard!D$14:D$28),14),"")} | E26: {=IFERROR(INDEX(Dashboard!E$14:E$28,MATCH(SMALL(IF(Dashboard!D$14:D$28>0,Dashboard!D$14:D$28,1E+99),14),Dashboard!D$14:D$28,0)),"")} | F26: {=IFERROR(INDEX(Dashboard!F$14:F$28,MATCH(SMALL(IF(Dashboard!D$14:D$28>0,Dashboard!D$14:D$28,1E+99),14),Dashboard!D$14:D$28,0)),"")} | G26: =IFERROR(IF(D26="","",SUM(H13:H25)-SUM(F13:F25)+$E$9),"") | H26: =IFERROR(IF(D26="","",F26+G26),"") | I26: =IFERROR(IF(D26="","",IF(E26=0,D26/H26,NPER(E26/12,-H26,D26))),"") | J26: =IFERROR(IF(D26="","",DATE(YEAR(TODAY()),MONTH(TODAY())+I26,DAY(TODAY()))),"") | K26: =IFERROR(IF(D26="","",(H26*I26)-D26),"")
B27: 15 | C27: {=IFERROR(INDEX(Dashboard!B$14:B$28,MATCH(SMALL(IF(Dashboard!D$14:D$28>0,Dashboard!D$14:D$28,1E+99),15),Dashboard!D$14:D$28,0)),"")} | D27: {=IFERROR(SMALL(IF(Dashboard!D$14:D$28>0,Dashboard!D$14:D$28),15),"")} | E27: {=IFERROR(INDEX(Dashboard!E$14:E$28,MATCH(SMALL(IF(Dashboard!D$14:D$28>0,Dashboard!D$14:D$28,1E+99),15),Dashboard!D$14:D$28,0)),"")} | F27: {=IFERROR(INDEX(Dashboard!F$14:F$28,MATCH(SMALL(IF(Dashboard!D$14:D$28>0,Dashboard!D$14:D$28,1E+99),15),Dashboard!D$14:D$28,0)),"")} | G27: =IFERROR(IF(D27="","",SUM(H13:H26)-SUM(F13:F26)+$E$9),"") | H27: =IFERROR(IF(D27="","",F27+G27),"") | I27: =IFERROR(IF(D27="","",IF(E27=0,D27/H27,NPER(E27/12,-H27,D27))),"") | J27: =IFERROR(IF(D27="","",DATE(YEAR(TODAY()),MONTH(TODAY())+I27,DAY(TODAY()))),"") | K27: =IFERROR(IF(D27="","",(H27*I27)-D27),"")
B28: TOTALS | D28: =SUM(D13:D27) -> 46400 | F28: =SUM(F13:F27) -> 845 | I28: =MAX(I13:I27) -> 14.605057 | K28: =SUM(K13:K27) -> 2101.5933
B30: SNOWBALL ROLLOVER CASCADE
B32: Step 1: Pay off smallest debt | E32: =IF(C13="","",C13&": "&TEXT(H13,"$#,##0")&"/mo --> PAID OFF!") -> Credit Card B: $285,0/mo --> PAID OFF!
C33: |
B34: Step 2: Roll payment into next debt | E34: =IF(C14="","",C14&": "&TEXT(F14,"$#,##0")&" min + "&TEXT(H13,"$#,##0")&" rollover = "&TEXT(F14+H13,"$#,##0")&"/mo") -> Credit Card A: $130,0 min + $285,0 rollover = $415,0/mo
C35: |
B36: Step 3: Roll combined payment into next | E36: =IF(C15="","",C15&": "&TEXT(F15,"$#,##0")&" min + "&TEXT(F14+H13,"$#,##0")&" rollover = "&TEXT(F15+F14+H13,"$#,##0")&"/mo") -> Car Loan: $350,0 min + $415,0 rollover = $765,0/mo
C37: |
B38: Step 4: Snowball keeps growing! | E38: =IF(C16="","","Each payoff makes the next payment BIGGER and FASTER!") -> Each payoff makes the next payment BIGGER and FASTER!
B41: SNOWBALL METHOD SUMMARY
B42: Total Months to Debt-Free: | F42: =MAX(I13:I27) -> 14.605057
B43: Total Interest You Will Pay: | F43: =SUM(K13:K27) -> 2101.5933
B44: Total Cost of All Debt: | F44: =SUM(D13:D27)+SUM(K13:K27) -> 48501.593

Sheet Avalanche Method
B2: DEBT AVALANCHE METHOD
B5: The Debt Avalanche Method: Pay minimum payments on ALL debts, then throw every extra dollar at the HIGHEST INTEREST RATE first. When that debt is paid off, roll its entire payment into the next highest-rate debt. This method saves you the most money in total interest paid over the life of your debts.
B9: Extra Monthly Payment: | E9: 200 | F9: (Enter debts on Dashboard tab. This tab auto-calculates from that data.)
B11: AVALANCHE PAYOFF ORDER (Highest Interest Rate First)
B12: Priority | C12: Debt Name | D12: Balance | E12: APR | F12: Min Payment | G12: Extra Payment | H12: Total Payment | I12: Months to Payoff | J12: Est. Payoff Date | K12: Total Interest
B13: 1 | C13: {=IFERROR(INDEX(Dashboard!B$14:B$28,MATCH(LARGE(IF(Dashboard!D$14:D$28>0,Dashboard!E$14:E$28,-1),1),Dashboard!E$14:E$28,0)),"")} -> Credit Card B | D13: {=IFERROR(INDEX(Dashboard!D$14:D$28,MATCH(LARGE(IF(Dashboard!D$14:D$28>0,Dashboard!E$14:E$28,-1),1),Dashboard!E$14:E$28,0)),"")} -> 3100 | E13: {=IFERROR(LARGE(IF(Dashboard!D$14:D$28>0,Dashboard!E$14:E$28),1),"")} -> 0.2299 | F13: {=IFERROR(INDEX(Dashboard!F$14:F$28,MATCH(LARGE(IF(Dashboard!D$14:D$28>0,Dashboard!E$14:E$28,-1),1),Dashboard!E$14:E$28,0)),"")} -> 85 | G13: =$E$9 -> 200 | H13: =IFERROR(IF(D13="","",F13+G13),"") -> 285 | I13: =IFERROR(IF(D13="","",IF(E13=0,D13/H13,NPER(E13/12,-H13,D13))),"") -> 12.314039 | J13: =IFERROR(IF(D13="","",DATE(YEAR(TODAY()),MONTH(TODAY())+I13,DAY(TODAY()))),"") -> 46441 | K13: =IFERROR(IF(D13="","",(H13*I13)-D13),"") -> 409.50101
B14: 2 | C14: {=IFERROR(INDEX(Dashboard!B$14:B$28,MATCH(LARGE(IF(Dashboard!D$14:D$28>0,Dashboard!E$14:E$28,-1),2),Dashboard!E$14:E$28,0)),"")} -> Credit Card A | D14: {=IFERROR(INDEX(Dashboard!D$14:D$28,MATCH(LARGE(IF(Dashboard!D$14:D$28>0,Dashboard!E$14:E$28,-1),2),Dashboard!E$14:E$28,0)),"")} -> 4800 | E14: {=IFERROR(LARGE(IF(Dashboard!D$14:D$28>0,Dashboard!E$14:E$28),2),"")} -> 0.1999 | F14: {=IFERROR(INDEX(Dashboard!F$14:F$28,MATCH(LARGE(IF(Dashboard!D$14:D$28>0,Dashboard!E$14:E$28,-1),2),Dashboard!E$14:E$28,0)),"")} -> 130 | G14: =IFERROR(IF(D14="","",SUM(H13:H13)-SUM(F13:F13)+$E$9),"") -> 400 | H14: =IFERROR(IF(D14="","",F14+G14),"") -> 530 | I14: =IFERROR(IF(D14="","",IF(E14=0,D14/H14,NPER(E14/12,-H14,D14))),"") -> 9.8988861 | J14: =IFERROR(IF(D14="","",DATE(YEAR(TODAY()),MONTH(TODAY())+I14,DAY(TODAY()))),"") -> 46349 | K14: =IFERROR(IF(D14="","",(H14*I14)-D14),"") -> 446.40964
B15: 3 | C15: {=IFERROR(INDEX(Dashboard!B$14:B$28,MATCH(LARGE(IF(Dashboard!D$14:D$28>0,Dashboard!E$14:E$28,-1),3),Dashboard!E$14:E$28,0)),"")} -> Student Loan | D15: {=IFERROR(INDEX(Dashboard!D$14:D$28,MATCH(LARGE(IF(Dashboard!D$14:D$28>0,Dashboard!E$14:E$28,-1),3),Dashboard!E$14:E$28,0)),"")} -> 26500 | E15: {=IFERROR(LARGE(IF(Dashboard!D$14:D$28>0,Dashboard!E$14:E$28),3),"")} -> 0.055 | F15: {=IFERROR(INDEX(Dashboard!F$14:F$28,MATCH(LARGE(IF(Dashboard!D$14:D$28>0,Dashboard!E$14:E$28,-1),3),Dashboard!E$14:E$28,0)),"")} -> 280 | G15: =IFERROR(IF(D15="","",SUM(H13:H14)-SUM(F13:F14)+$E$9),"") -> 800 | H15: =IFERROR(IF(D15="","",F15+G15),"") -> 1080 | I15: =IFERROR(IF(D15="","",IF(E15=0,D15/H15,NPER(E15/12,-H15,D15))),"") -> 26.089414 | J15: =IFERROR(IF(D15="","",DATE(YEAR(TODAY()),MONTH(TODAY())+I15,DAY(TODAY()))),"") -> 46866 | K15: =IFERROR(IF(D15="","",(H15*I15)-D15),"") -> 1676.5676
B16: 4 | C16: {=IFERROR(INDEX(Dashboard!B$14:B$28,MATCH(LARGE(IF(Dashboard!D$14:D$28>0,Dashboard!E$14:E$28,-1),4),Dashboard!E$14:E$28,0)),"")} -> Car Loan | D16: {=IFERROR(INDEX(Dashboard!D$14:D$28,MATCH(LARGE(IF(Dashboard!D$14:D$28>0,Dashboard!E$14:E$28,-1),4),Dashboard!E$14:E$28,0)),"")} -> 12000 | E16: {=IFERROR(LARGE(IF(Dashboard!D$14:D$28>0,Dashboard!E$14:E$28),4),"")} -> 0.049 | F16: {=IFERROR(INDEX(Dashboard!F$14:F$28,MATCH(LARGE(IF(Dashboard!D$14:D$28>0,Dashboard!E$14:E$28,-1),4),Dashboard!E$14:E$28,0)),"")} -> 350 | G16: =IFERROR(IF(D16="","",SUM(H13:H15)-SUM(F13:F15)+$E$9),"") -> 1600 | H16: =IFERROR(IF(D16="","",F16+G16),"") -> 1950 | I16: =IFERROR(IF(D16="","",IF(E16=0,D16/H16,NPER(E16/12,-H16,D16))),"") -> 6.2451999 | J16: =IFERROR(IF(D16="","",DATE(YEAR(TODAY()),MONTH(TODAY())+I16,DAY(TODAY()))),"") -> 46257 | K16: =IFERROR(IF(D16="","",(H16*I16)-D16),"") -> 178.13974
B17: 5 | C17: {=IFERROR(INDEX(Dashboard!B$14:B$28,MATCH(LARGE(IF(Dashboard!D$14:D$28>0,Dashboard!E$14:E$28,-1),5),Dashboard!E$14:E$28,0)),"")} | D17: {=IFERROR(INDEX(Dashboard!D$14:D$28,MATCH(LARGE(IF(Dashboard!D$14:D$28>0,Dashboard!E$14:E$28,-1),5),Dashboard!E$14:E$28,0)),"")} | E17: {=IFERROR(LARGE(IF(Dashboard!D$14:D$28>0,Dashboard!E$14:E$28),5),"")} | F17: {=IFERROR(INDEX(Dashboard!F$14:F$28,MATCH(LARGE(IF(Dashboard!D$14:D$28>0,Dashboard!E$14:E$28,-1),5),Dashboard!E$14:E$28,0)),"")} | G17: =IFERROR(IF(D17="","",SUM(H13:H16)-SUM(F13:F16)+$E$9),"") | H17: =IFERROR(IF(D17="","",F17+G17),"") | I17: =IFERROR(IF(D17="","",IF(E17=0,D17/H17,NPER(E17/12,-H17,D17))),"") | J17: =IFERROR(IF(D17="","",DATE(YEAR(TODAY()),MONTH(TODAY())+I17,DAY(TODAY()))),"") | K17: =IFERROR(IF(D17="","",(H17*I17)-D17),"")
B18: 6 | C18: {=IFERROR(INDEX(Dashboard!B$14:B$28,MATCH(LARGE(IF(Dashboard!D$14:D$28>0,Dashboard!E$14:E$28,-1),6),Dashboard!E$14:E$28,0)),"")} | D18: {=IFERROR(INDEX(Dashboard!D$14:D$28,MATCH(LARGE(IF(Dashboard!D$14:D$28>0,Dashboard!E$14:E$28,-1),6),Dashboard!E$14:E$28,0)),"")} | E18: {=IFERROR(LARGE(IF(Dashboard!D$14:D$28>0,Dashboard!E$14:E$28),6),"")} | F18: {=IFERROR(INDEX(Dashboard!F$14:F$28,MATCH(LARGE(IF(Dashboard!D$14:D$28>0,Dashboard!E$14:E$28,-1),6),Dashboard!E$14:E$28,0)),"")} | G18: =IFERROR(IF(D18="","",SUM(H13:H17)-SUM(F13:F17)+$E$9),"") | H18: =IFERROR(IF(D18="","",F18+G18),"") | I18: =IFERROR(IF(D18="","",IF(E18=0,D18/H18,NPER(E18/12,-H18,D18))),"") | J18: =IFERROR(IF(D18="","",DATE(YEAR(TODAY()),MONTH(TODAY())+I18,DAY(TODAY()))),"") | K18: =IFERROR(IF(D18="","",(H18*I18)-D18),"")
B19: 7 | C19: {=IFERROR(INDEX(Dashboard!B$14:B$28,MATCH(LARGE(IF(Dashboard!D$14:D$28>0,Dashboard!E$14:E$28,-1),7),Dashboard!E$14:E$28,0)),"")} | D19: {=IFERROR(INDEX(Dashboard!D$14:D$28,MATCH(LARGE(IF(Dashboard!D$14:D$28>0,Dashboard!E$14:E$28,-1),7),Dashboard!E$14:E$28,0)),"")} | E19: {=IFERROR(LARGE(IF(Dashboard!D$14:D$28>0,Dashboard!E$14:E$28),7),"")} | F19: {=IFERROR(INDEX(Dashboard!F$14:F$28,MATCH(LARGE(IF(Dashboard!D$14:D$28>0,Dashboard!E$14:E$28,-1),7),Dashboard!E$14:E$28,0)),"")} | G19: =IFERROR(IF(D19="","",SUM(H13:H18)-SUM(F13:F18)+$E$9),"") | H19: =IFERROR(IF(D19="","",F19+G19),"") | I19: =IFERROR(IF(D19="","",IF(E19=0,D19/H19,NPER(E19/12,-H19,D19))),"") | J19: =IFERROR(IF(D19="","",DATE(YEAR(TODAY()),MONTH(TODAY())+I19,DAY(TODAY()))),"") | K19: =IFERROR(IF(D19="","",(H19*I19)-D19),"")
B20: 8 | C20: {=IFERROR(INDEX(Dashboard!B$14:B$28,MATCH(LARGE(IF(Dashboard!D$14:D$28>0,Dashboard!E$14:E$28,-1),8),Dashboard!E$14:E$28,0)),"")} | D20: {=IFERROR(INDEX(Dashboard!D$14:D$28,MATCH(LARGE(IF(Dashboard!D$14:D$28>0,Dashboard!E$14:E$28,-1),8),Dashboard!E$14:E$28,0)),"")} | E20: {=IFERROR(LARGE(IF(Dashboard!D$14:D$28>0,Dashboard!E$14:E$28),8),"")} | F20: {=IFERROR(INDEX(Dashboard!F$14:F$28,MATCH(LARGE(IF(Dashboard!D$14:D$28>0,Dashboard!E$14:E$28,-1),8),Dashboard!E$14:E$28,0)),"")} | G20: =IFERROR(IF(D20="","",SUM(H13:H19)-SUM(F13:F19)+$E$9),"") | H20: =IFERROR(IF(D20="","",F20+G20),"") | I20: =IFERROR(IF(D20="","",IF(E20=0,D20/H20,NPER(E20/12,-H20,D20))),"") | J20: =IFERROR(IF(D20="","",DATE(YEAR(TODAY()),MONTH(TODAY())+I20,DAY(TODAY()))),"") | K20: =IFERROR(IF(D20="","",(H20*I20)-D20),"")
B21: 9 | C21: {=IFERROR(INDEX(Dashboard!B$14:B$28,MATCH(LARGE(IF(Dashboard!D$14:D$28>0,Dashboard!E$14:E$28,-1),9),Dashboard!E$14:E$28,0)),"")} | D21: {=IFERROR(INDEX(Dashboard!D$14:D$28,MATCH(LARGE(IF(Dashboard!D$14:D$28>0,Dashboard!E$14:E$28,-1),9),Dashboard!E$14:E$28,0)),"")} | E21: {=IFERROR(LARGE(IF(Dashboard!D$14:D$28>0,Dashboard!E$14:E$28),9),"")} | F21: {=IFERROR(INDEX(Dashboard!F$14:F$28,MATCH(LARGE(IF(Dashboard!D$14:D$28>0,Dashboard!E$14:E$28,-1),9),Dashboard!E$14:E$28,0)),"")} | G21: =IFERROR(IF(D21="","",SUM(H13:H20)-SUM(F13:F20)+$E$9),"") | H21: =IFERROR(IF(D21="","",F21+G21),"") | I21: =IFERROR(IF(D21="","",IF(E21=0,D21/H21,NPER(E21/12,-H21,D21))),"") | J21: =IFERROR(IF(D21="","",DATE(YEAR(TODAY()),MONTH(TODAY())+I21,DAY(TODAY()))),"") | K21: =IFERROR(IF(D21="","",(H21*I21)-D21),"")
B22: 10 | C22: {=IFERROR(INDEX(Dashboard!B$14:B$28,MATCH(LARGE(IF(Dashboard!D$14:D$28>0,Dashboard!E$14:E$28,-1),10),Dashboard!E$14:E$28,0)),"")} | D22: {=IFERROR(INDEX(Dashboard!D$14:D$28,MATCH(LARGE(IF(Dashboard!D$14:D$28>0,Dashboard!E$14:E$28,-1),10),Dashboard!E$14:E$28,0)),"")} | E22: {=IFERROR(LARGE(IF(Dashboard!D$14:D$28>0,Dashboard!E$14:E$28),10),"")} | F22: {=IFERROR(INDEX(Dashboard!F$14:F$28,MATCH(LARGE(IF(Dashboard!D$14:D$28>0,Dashboard!E$14:E$28,-1),10),Dashboard!E$14:E$28,0)),"")} | G22: =IFERROR(IF(D22="","",SUM(H13:H21)-SUM(F13:F21)+$E$9),"") | H22: =IFERROR(IF(D22="","",F22+G22),"") | I22: =IFERROR(IF(D22="","",IF(E22=0,D22/H22,NPER(E22/12,-H22,D22))),"") | J22: =IFERROR(IF(D22="","",DATE(YEAR(TODAY()),MONTH(TODAY())+I22,DAY(TODAY()))),"") | K22: =IFERROR(IF(D22="","",(H22*I22)-D22),"")
B23: 11 | C23: {=IFERROR(INDEX(Dashboard!B$14:B$28,MATCH(LARGE(IF(Dashboard!D$14:D$28>0,Dashboard!E$14:E$28,-1),11),Dashboard!E$14:E$28,0)),"")} | D23: {=IFERROR(INDEX(Dashboard!D$14:D$28,MATCH(LARGE(IF(Dashboard!D$14:D$28>0,Dashboard!E$14:E$28,-1),11),Dashboard!E$14:E$28,0)),"")} | E23: {=IFERROR(LARGE(IF(Dashboard!D$14:D$28>0,Dashboard!E$14:E$28),11),"")} | F23: {=IFERROR(INDEX(Dashboard!F$14:F$28,MATCH(LARGE(IF(Dashboard!D$14:D$28>0,Dashboard!E$14:E$28,-1),11),Dashboard!E$14:E$28,0)),"")} | G23: =IFERROR(IF(D23="","",SUM(H13:H22)-SUM(F13:F22)+$E$9),"") | H23: =IFERROR(IF(D23="","",F23+G23),"") | I23: =IFERROR(IF(D23="","",IF(E23=0,D23/H23,NPER(E23/12,-H23,D23))),"") | J23: =IFERROR(IF(D23="","",DATE(YEAR(TODAY()),MONTH(TODAY())+I23,DAY(TODAY()))),"") | K23: =IFERROR(IF(D23="","",(H23*I23)-D23),"")
B24: 12 | C24: {=IFERROR(INDEX(Dashboard!B$14:B$28,MATCH(LARGE(IF(Dashboard!D$14:D$28>0,Dashboard!E$14:E$28,-1),12),Dashboard!E$14:E$28,0)),"")} | D24: {=IFERROR(INDEX(Dashboard!D$14:D$28,MATCH(LARGE(IF(Dashboard!D$14:D$28>0,Dashboard!E$14:E$28,-1),12),Dashboard!E$14:E$28,0)),"")} | E24: {=IFERROR(LARGE(IF(Dashboard!D$14:D$28>0,Dashboard!E$14:E$28),12),"")} | F24: {=IFERROR(INDEX(Dashboard!F$14:F$28,MATCH(LARGE(IF(Dashboard!D$14:D$28>0,Dashboard!E$14:E$28,-1),12),Dashboard!E$14:E$28,0)),"")} | G24: =IFERROR(IF(D24="","",SUM(H13:H23)-SUM(F13:F23)+$E$9),"") | H24: =IFERROR(IF(D24="","",F24+G24),"") | I24: =IFERROR(IF(D24="","",IF(E24=0,D24/H24,NPER(E24/12,-H24,D24))),"") | J24: =IFERROR(IF(D24="","",DATE(YEAR(TODAY()),MONTH(TODAY())+I24,DAY(TODAY()))),"") | K24: =IFERROR(IF(D24="","",(H24*I24)-D24),"")
B25: 13 | C25: {=IFERROR(INDEX(Dashboard!B$14:B$28,MATCH(LARGE(IF(Dashboard!D$14:D$28>0,Dashboard!E$14:E$28,-1),13),Dashboard!E$14:E$28,0)),"")} | D25: {=IFERROR(INDEX(Dashboard!D$14:D$28,MATCH(LARGE(IF(Dashboard!D$14:D$28>0,Dashboard!E$14:E$28,-1),13),Dashboard!E$14:E$28,0)),"")} | E25: {=IFERROR(LARGE(IF(Dashboard!D$14:D$28>0,Dashboard!E$14:E$28),13),"")} | F25: {=IFERROR(INDEX(Dashboard!F$14:F$28,MATCH(LARGE(IF(Dashboard!D$14:D$28>0,Dashboard!E$14:E$28,-1),13),Dashboard!E$14:E$28,0)),"")} | G25: =IFERROR(IF(D25="","",SUM(H13:H24)-SUM(F13:F24)+$E$9),"") | H25: =IFERROR(IF(D25="","",F25+G25),"") | I25: =IFERROR(IF(D25="","",IF(E25=0,D25/H25,NPER(E25/12,-H25,D25))),"") | J25: =IFERROR(IF(D25="","",DATE(YEAR(TODAY()),MONTH(TODAY())+I25,DAY(TODAY()))),"") | K25: =IFERROR(IF(D25="","",(H25*I25)-D25),"")
B26: 14 | C26: {=IFERROR(INDEX(Dashboard!B$14:B$28,MATCH(LARGE(IF(Dashboard!D$14:D$28>0,Dashboard!E$14:E$28,-1),14),Dashboard!E$14:E$28,0)),"")} | D26: {=IFERROR(INDEX(Dashboard!D$14:D$28,MATCH(LARGE(IF(Dashboard!D$14:D$28>0,Dashboard!E$14:E$28,-1),14),Dashboard!E$14:E$28,0)),"")} | E26: {=IFERROR(LARGE(IF(Dashboard!D$14:D$28>0,Dashboard!E$14:E$28),14),"")} | F26: {=IFERROR(INDEX(Dashboard!F$14:F$28,MATCH(LARGE(IF(Dashboard!D$14:D$28>0,Dashboard!E$14:E$28,-1),14),Dashboard!E$14:E$28,0)),"")} | G26: =IFERROR(IF(D26="","",SUM(H13:H25)-SUM(F13:F25)+$E$9),"") | H26: =IFERROR(IF(D26="","",F26+G26),"") | I26: =IFERROR(IF(D26="","",IF(E26=0,D26/H26,NPER(E26/12,-H26,D26))),"") | J26: =IFERROR(IF(D26="","",DATE(YEAR(TODAY()),MONTH(TODAY())+I26,DAY(TODAY()))),"") | K26: =IFERROR(IF(D26="","",(H26*I26)-D26),"")
B27: 15 | C27: {=IFERROR(INDEX(Dashboard!B$14:B$28,MATCH(LARGE(IF(Dashboard!D$14:D$28>0,Dashboard!E$14:E$28,-1),15),Dashboard!E$14:E$28,0)),"")} | D27: {=IFERROR(INDEX(Dashboard!D$14:D$28,MATCH(LARGE(IF(Dashboard!D$14:D$28>0,Dashboard!E$14:E$28,-1),15),Dashboard!E$14:E$28,0)),"")} | E27: {=IFERROR(LARGE(IF(Dashboard!D$14:D$28>0,Dashboard!E$14:E$28),15),"")} | F27: {=IFERROR(INDEX(Dashboard!F$14:F$28,MATCH(LARGE(IF(Dashboard!D$14:D$28>0,Dashboard!E$14:E$28,-1),15),Dashboard!E$14:E$28,0)),"")} | G27: =IFERROR(IF(D27="","",SUM(H13:H26)-SUM(F13:F26)+$E$9),"") | H27: =IFERROR(IF(D27="","",F27+G27),"") | I27: =IFERROR(IF(D27="","",IF(E27=0,D27/H27,NPER(E27/12,-H27,D27))),"") | J27: =IFERROR(IF(D27="","",DATE(YEAR(TODAY()),MONTH(TODAY())+I27,DAY(TODAY()))),"") | K27: =IFERROR(IF(D27="","",(H27*I27)-D27),"")
B28: TOTALS | D28: =SUM(D13:D27) -> 46400 | F28: =SUM(F13:F27) -> 845 | I28: =MAX(I13:I27) -> 26.089414 | K28: =SUM(K13:K27) -> 2710.618
B30: AVALANCHE ROLLOVER CASCADE
B32: Step 1: Attack highest-rate debt | E32: =IF(C13="","",C13&" ("&TEXT(E13,"0.00%")&"): "&TEXT(H13,"$#,##0")&"/mo --> PAID OFF!") -> Credit Card B (023%): $285,0/mo --> PAID OFF!
C33: |
B34: Step 2: Roll payment to next highest rate | E34: =IF(C14="","",C14&" ("&TEXT(E14,"0.00%")&"): "&TEXT(F14,"$#,##0")&" min + "&TEXT(H13,"$#,##0")&" rollover = "&TEXT(F14+H13,"$#,##0")&"/mo") -> Credit Card A (020%): $130,0 min + $285,0 rollover = $415,0/mo
C35: |
B36: Step 3: Combined payment hits next debt | E36: =IF(C15="","",C15&" ("&TEXT(E15,"0.00%")&"): "&TEXT(F15,"$#,##0")&" min + "&TEXT(F14+H13,"$#,##0")&" rollover") -> Student Loan (006%): $280,0 min + $415,0 rollover
C37: |
B38: Step 4: Maximum interest savings! | E38: =IF(C16="","","You save the MOST money by killing high-interest debt first!") -> You save the MOST money by killing high-interest debt first!
B41: AVALANCHE METHOD SUMMARY
B42: Total Months to Debt-Free: | F42: =MAX(I13:I27) -> 26.089414
B43: Total Interest You Will Pay: | F43: =SUM(K13:K27) -> 2710.618
B44: Total Cost of All Debt: | F44: =SUM(D13:D27)+SUM(K13:K27) -> 49110.618

Sheet Method Comparison
B2: METHOD COMPARISON
B4: Snowball vs Avalanche: Which Strategy is Best for You?
B6: SIDE-BY-SIDE COMPARISON
B7: Metric | C7: Snowball Method | D7: Avalanche Method | E7: Difference
B8: Total Months to Debt-Free | C8: ='Snowball Method'!I28 -> 14.605057 | D8: ='Avalanche Method'!I28 -> 26.089414 | E8: =C8-D8 -> -11.484357
B9: Total Interest Paid | C9: ='Snowball Method'!K28 -> 2101.5933 | D9: ='Avalanche Method'!K28 -> 2710.618 | E9: =C9-D9 -> -609.0247
B10: Total Cost of Debt | C10: ='Snowball Method'!K28+'Snowball Method'!D28 -> 48501.593 | D10: ='Avalanche Method'!K28+'Avalanche Method'!D28 -> 49110.618 | E10: =C10-D10 -> -609.0247
B12: PROS & CONS
C13: Snowball | D13: Avalanche
B14: Pros | C14: Quick wins build motivation | D14: Saves the most money in interest | E14: Pros
C15: Simple to understand | D15: Mathematically optimal
C16: Psychological momentum | D16: Faster total debt elimination*
B17: Cons | C17: Costs more in total interest | D17: Largest debts may take longer | E17: Cons
C18: Not mathematically optimal | D18: Can feel slow at first
D19: Requires more discipline
B21: RECOMMENDATION: If motivation and quick wins matter most to you, choose the SNOWBALL method. If saving the most money in interest is your priority, choose the AVALANCHE method. Either way, the best method is the one you will stick with!
B24: "WHAT IF" SCENARIOS
B25: See what happens when you increase your extra monthly payment:
B27: Scenario | C27: Extra $/Month Added | D27: Estimated Months Saved* | E27: Estimated Interest Saved*
B28: Add $50/month extra | C28: 50 | D28: =IFERROR(IFERROR(NPER((IFERROR(SUMPRODUCT(Dashboard!D14:D28,Dashboard!E14:E28)/SUM(Dashboard!D14:D28),0.1))/12,-(SUM(Dashboard!F14:F28)+'Snowball Method'!E9),SUM(Dashboard!D14:D28)),0)-IFERROR(NPER((IFERROR(SUMPRODUCT(Dashboard!D14:D28,Dashboard!E14:E28)/SUM(Dashboard!D14:D28),0.1))/12,-(SUM(Dashboard!F14:F28)+'Snowball Method'!E9+50),SUM(Dashboard!D14:D28)),0),"-") -> 2.8640092 | E28: =IFERROR(((SUM(Dashboard!F14:F28)+'Snowball Method'!E9)*IFERROR(NPER((IFERROR(SUMPRODUCT(Dashboard!D14:D28,Dashboard!E14:E28)/SUM(Dashboard!D14:D28),0.1))/12,-(SUM(Dashboard!F14:F28)+'Snowball Method'!E9),SUM(Dashboard!D14:D28)),0)-SUM(Dashboard!D14:D28))-((SUM(Dashboard!F14:F28)+'Snowball Method'!E9+50)*IFERROR(NPER((IFERROR(SUMPRODUCT(Dashboard!D14:D28,Dashboard!E14:E28)/SUM(Dashboard!D14:D28),0.1))/12,-(SUM(Dashboard!F14:F28)+'Snowball Method'!E9+50),SUM(Dashboard!D14:D28)),0)-SUM(Dashboard!D14:D28)),"-") -> 494.04397
B29: Add $100/month extra | C29: 100 | D29: =IFERROR(IFERROR(NPER((IFERROR(SUMPRODUCT(Dashboard!D14:D28,Dashboard!E14:E28)/SUM(Dashboard!D14:D28),0.1))/12,-(SUM(Dashboard!F14:F28)+'Snowball Method'!E9),SUM(Dashboard!D14:D28)),0)-IFERROR(NPER((IFERROR(SUMPRODUCT(Dashboard!D14:D28,Dashboard!E14:E28)/SUM(Dashboard!D14:D28),0.1))/12,-(SUM(Dashboard!F14:F28)+'Snowball Method'!E9+100),SUM(Dashboard!D14:D28)),0),"-") -> 5.4310826 | E29: =IFERROR(((SUM(Dashboard!F14:F28)+'Snowball Method'!E9)*IFERROR(NPER((IFERROR(SUMPRODUCT(Dashboard!D14:D28,Dashboard!E14:E28)/SUM(Dashboard!D14:D28),0.1))/12,-(SUM(Dashboard!F14:F28)+'Snowball Method'!E9),SUM(Dashboard!D14:D28)),0)-SUM(Dashboard!D14:D28))-((SUM(Dashboard!F14:F28)+'Snowball Method'!E9+100)*IFERROR(NPER((IFERROR(SUMPRODUCT(Dashboard!D14:D28,Dashboard!E14:E28)/SUM(Dashboard!D14:D28),0.1))/12,-(SUM(Dashboard!F14:F28)+'Snowball Method'!E9+100),SUM(Dashboard!D14:D28)),0)-SUM(Dashboard!D14:D28)),"-") -> 934.49735
B30: Add $200/month extra | C30: 200 | D30: =IFERROR(IFERROR(NPER((IFERROR(SUMPRODUCT(Dashboard!D14:D28,Dashboard!E14:E28)/SUM(Dashboard!D14:D28),0.1))/12,-(SUM(Dashboard!F14:F28)+'Snowball Method'!E9),SUM(Dashboard!D14:D28)),0)-IFERROR(NPER((IFERROR(SUMPRODUCT(Dashboard!D14:D28,Dashboard!E14:E28)/SUM(Dashboard!D14:D28),0.1))/12,-(SUM(Dashboard!F14:F28)+'Snowball Method'!E9+200),SUM(Dashboard!D14:D28)),0),"-") -> 9.8429032 | E30: =IFERROR(((SUM(Dashboard!F14:F28)+'Snowball Method'!E9)*IFERROR(NPER((IFERROR(SUMPRODUCT(Dashboard!D14:D28,Dashboard!E14:E28)/SUM(Dashboard!D14:D28),0.1))/12,-(SUM(Dashboard!F14:F28)+'Snowball Method'!E9),SUM(Dashboard!D14:D28)),0)-SUM(Dashboard!D14:D28))-((SUM(Dashboard!F14:F28)+'Snowball Method'!E9+200)*IFERROR(NPER((IFERROR(SUMPRODUCT(Dashboard!D14:D28,Dashboard!E14:E28)/SUM(Dashboard!D14:D28),0.1))/12,-(SUM(Dashboard!F14:F28)+'Snowball Method'!E9+200),SUM(Dashboard!D14:D28)),0)-SUM(Dashboard!D14:D28)),"-") -> 1686.23
B31: Add $500/month extra | C31: 500 | D31: =IFERROR(IFERROR(NPER((IFERROR(SUMPRODUCT(Dashboard!D14:D28,Dashboard!E14:E28)/SUM(Dashboard!D14:D28),0.1))/12,-(SUM(Dashboard!F14:F28)+'Snowball Method'!E9),SUM(Dashboard!D14:D28)),0)-IFERROR(NPER((IFERROR(SUMPRODUCT(Dashboard!D14:D28,Dashboard!E14:E28)/SUM(Dashboard!D14:D28),0.1))/12,-(SUM(Dashboard!F14:F28)+'Snowball Method'!E9+500),SUM(Dashboard!D14:D28)),0),"-") -> 19.210942 | E31: =IFERROR(((SUM(Dashboard!F14:F28)+'Snowball Method'!E9)*IFERROR(NPER((IFERROR(SUMPRODUCT(Dashboard!D14:D28,Dashboard!E14:E28)/SUM(Dashboard!D14:D28),0.1))/12,-(SUM(Dashboard!F14:F28)+'Snowball Method'!E9),SUM(Dashboard!D14:D28)),0)-SUM(Dashboard!D14:D28))-((SUM(Dashboard!F14:F28)+'Snowball Method'!E9+500)*IFERROR(NPER((IFERROR(SUMPRODUCT(Dashboard!D14:D28,Dashboard!E14:E28)/SUM(Dashboard!D14:D28),0.1))/12,-(SUM(Dashboard!F14:F28)+'Snowball Method'!E9+500),SUM(Dashboard!D14:D28)),0)-SUM(Dashboard!D14:D28)),"-") -> 3260.4447
B33: * Estimates based on weighted average interest rate. Actual results may vary by payoff order.

Sheet Payment Log
B2: PAYMENT LOG
B4: Track every payment you make toward becoming debt-free
B6: Total Payments Logged: | D6: =COUNTA(B9:B108) -> 0 | E6: Total Amount Paid: | G6: =SUM(D9:D108) -> 0
B8: Date | C8: Debt Name | D8: Payment Amount | E8: Type | F8: Running Balance | G8: Notes
F9: =IFERROR(IF(D9="","",SUM(Dashboard!D14:D28)-D9),"")
F10: =IFERROR(IF(D10="","",F9-D10),"")
F11: =IFERROR(IF(D11="","",F10-D11),"")
F12: =IFERROR(IF(D12="","",F11-D12),"")
F13: =IFERROR(IF(D13="","",F12-D13),"")
F14: =IFERROR(IF(D14="","",F13-D14),"")
F15: =IFERROR(IF(D15="","",F14-D15),"")
F16: =IFERROR(IF(D16="","",F15-D16),"")
F17: =IFERROR(IF(D17="","",F16-D17),"")
F18: =IFERROR(IF(D18="","",F17-D18),"")
F19: =IFERROR(IF(D19="","",F18-D19),"")
F20: =IFERROR(IF(D20="","",F19-D20),"")
F21: =IFERROR(IF(D21="","",F20-D21),"")
... F33: =IFERROR(IF(D33="","",F32-D33),"")
F34: =IFERROR(IF(D34="","",F33-D34),"") | G34: =CONCATENATE("Subtotal (rows 1-25): ",TEXT(SUM(D9:D33),"$#,##0.00")) -> Subtotal (rows 1-25): $,000
F35: =IFERROR(IF(D35="","",F34-D35),"")
F36: =IFERROR(IF(D36="","",F35-D36),"")
F37: =IFERROR(IF(D37="","",F36-D37),"")
F38: =IFERROR(IF(D38="","",F37-D38),"")
F39: =IFERROR(IF(D39="","",F38-D39),"")
F40: =IFERROR(IF(D40="","",F39-D40),"")
F41: =IFERROR(IF(D41="","",F40-D41),"")
F42: =IFERROR(IF(D42="","",F41-D42),"")
F43: =IFERROR(IF(D43="","",F42-D43),"")
F44: =IFERROR(IF(D44="","",F43-D44),"")
F45: =IFERROR(IF(D45="","",F44-D45),"")
F46: =IFERROR(IF(D46="","",F45-D46),"")
... F58: =IFERROR(IF(D58="","",F57-D58),"")
F59: =IFERROR(IF(D59="","",F58-D59),"") | G59: =CONCATENATE("Subtotal (rows 1-50): ",TEXT(SUM(D9:D58),"$#,##0.00")) -> Subtotal (rows 1-50): $,000
F60: =IFERROR(IF(D60="","",F59-D60),"")
F61: =IFERROR(IF(D61="","",F60-D61),"")
F62: =IFERROR(IF(D62="","",F61-D62),"")
F63: =IFERROR(IF(D63="","",F62-D63),"")
F64: =IFERROR(IF(D64="","",F63-D64),"")
F65: =IFERROR(IF(D65="","",F64-D65),"")
F66: =IFERROR(IF(D66="","",F65-D66),"")
...

Sheet Instructions
B2: DEBT PAYOFF TRACKER - INSTRUCTIONS
B5: Welcome to your Debt Payoff Tracker! This workbook is your complete toolkit for eliminating debt. It will help you organize your debts, compare payoff strategies, track your payments, and visualize your progress toward becoming debt-free.
B9: GETTING STARTED
B11: 1 | C11: MAKE A COPY: Save this file with your name (e.g., 'MyDebtTracker.xlsx') so you always have a clean original.
B13: 2 | C13: ENTER YOUR DEBTS: Go to the Dashboard tab and enter all your debts in the Debt Overview table. Include the debt name, original balance, current balance, interest rate (APR), and minimum monthly payment.
B15: 3 | C15: SET YOUR EXTRA PAYMENT: On the Snowball Method and Avalanche Method tabs, enter how much extra you can pay each month beyond your minimums in the 'Extra Monthly Payment' field.
B17: 4 | C17: REVIEW PAYOFF STRATEGIES: Check the Snowball Method tab (pay smallest balance first) and the Avalanche Method tab (pay highest interest first) to see your personalized payoff plans.
B19: 5 | C19: COMPARE METHODS: Visit the Method Comparison tab to see a side-by-side analysis. Try the 'What If' scenarios to see how extra payments accelerate your journey.
B21: 6 | C21: LOG YOUR PAYMENTS: Each time you make a payment, record it in the Payment Log tab. Select the date, debt name, amount, and type (Minimum, Extra, or Lump Sum).
B23: 7 | C23: UPDATE & CELEBRATE: As you make payments, update your Current Balance on the Dashboard. Watch your KPIs and progress percentage update automatically!
B27: KEY DEFINITIONS
B29: APR | C29: APR (Annual Percentage Rate): The yearly interest rate charged on your debt. A 19.99% APR means you pay about 1.67% per month on your remaining balance.
B31: Minimum Payment | C31: Minimum Payment: The smallest amount your lender requires you to pay each month. Paying only minimums means you'll be in debt much longer and pay far more in interest.
B33: Debt Snowball | C33: Debt Snowball: A payoff strategy where you attack the smallest balance first while paying minimums on everything else. Quick wins provide motivation.
B35: Debt Avalanche | C35: Debt Avalanche: A payoff strategy where you attack the highest interest rate first while paying minimums on everything else. This saves the most money mathematically.
B37: Principal | C37: Principal: The original amount borrowed, not including interest. When you make a payment, part goes to interest and part reduces the principal.
B39: Extra Payment | C39: Extra Payment: Any amount you pay above the minimum required payment. Extra payments go directly toward reducing your principal balance.
B41: Rollover Payment | C41: Rollover Payment: When you pay off one debt, you take its entire payment (minimum + extra) and add it to the next debt's payment. This is the 'snowball' or 'avalanche' effect.
B44: TIPS FOR PAYING OFF DEBT FASTER
B46: 1. | C46: Automate your payments so you never miss one. Set up automatic payments for at least the minimum on every debt.
B47: 2. | C47: Use windfalls wisely. Tax refunds, bonuses, and gifts can make huge dents in your debt when applied as lump-sum payments.
B48: 3. | C48: Cut one expense and redirect the savings. Cancel a subscription, eat out less, or downgrade a service. Every dollar counts.
B49: 4. | C49: Consider a balance transfer to a 0% APR card for high-interest credit card debt (but watch out for transfer fees and the promotional period end date).
B50: 5. | C50: Call your lenders and negotiate. Ask for a lower interest rate, especially if you have a good payment history. The worst they can say is no.
B51: 6. | C51: Track every payment in this workbook. Seeing your progress is one of the most powerful motivators to keep going.
B52: 7. | C52: Celebrate milestones! When you pay off a debt, acknowledge the achievement. It fuels motivation for the next one.
B53: 8. | C53: Do not take on new debt while paying off existing debt. Put the credit cards away and switch to cash or debit.
B54: 9. | C54: Build a small emergency fund ($500-$1,000) first so unexpected expenses don't derail your debt payoff plan.
B55: 10. | C55: Consider a side hustle or selling unused items. Even temporary extra income can dramatically accelerate your payoff timeline.
B58: FREQUENTLY ASKED QUESTIONS
B60: Q: Which method should I choose - Snowball or Avalanche?
B61: A: If you need motivation and quick wins, go with Snowball. If you want to save the most money in interest, go with Avalanche. The best method is the one you'll stick with consistently. Many people start with Snowball for motivation, then switch to Avalanche once they build momentum.
B63: Q: How accurate are the payoff estimates?
B64: A: The estimates use standard amortization formulas and assume consistent payments. Real results may vary slightly due to interest compounding methods, payment timing, and balance changes. They are excellent for planning and comparison purposes.
B66: Q: What if I can only pay minimums right now?
B67: A: That's okay! Enter $0 for Extra Monthly Payment. The tracker still works - it will show you how long minimum payments will take. As your situation improves, increase the extra payment amount to see the impact.
B69: Q: Should I save or pay off debt first?
B70: A: Financial experts generally recommend: 1) Build a small emergency fund ($500-$1,000), 2) Pay off high-interest debt (above 7-8%), 3) Build a full emergency fund, 4) Pay off remaining debt. But everyone's situation is unique.
B72: Q: How often should I update this tracker?
B73: A: Update your Current Balances on the Dashboard at least monthly, ideally after each statement. Log every payment in the Payment Log as you make it. Regular updating keeps you motivated and your projections accurate.
...
