Workbook

Sheet 📊 Dashboard
B2: BILL ORGANIZER & PAYMENT TRACKER
B3: Your complete monthly bill management dashboard
B5: ='📋 Bill List'!C42 -> 3054.96 | F5: =COUNTIF('✅ Monthly Checklist'!D5:D24,"Yes") -> 8 | J5: =COUNTIF('✅ Monthly Checklist'!D5:D24,"No")+COUNTIF('✅ Monthly Checklist'!D5:D24,"")-COUNTBLANK('✅ Monthly Checklist'!B5:B24)+COUNTIF('✅ Monthly Checklist'!D5:D24,"No")*0 -> 7
B6: Total Monthly Bills | F6: Bills Paid This Month | J6: Bills Remaining
B8: =COUNTIFS('✅ Monthly Checklist'!D5:D24,"<>Yes",'✅ Monthly Checklist'!B5:B24,"<>") -> 7 | F8: ='📱 Subscription Tracker'!C22 -> 121.92 | J8: ='📋 Bill List'!C43 -> 36659.52
B9: Overdue Bills | F9: Total Subscriptions | J9: Annual Bill Total
B12: MONTHLY SUMMARY | I12: CATEGORY BREAKDOWN
B13: Month | C13: Total Bills | D13: Paid | E13: Unpaid | F13: Amount Due | G13: Amount Paid | H13: Balance | I13: Category | J13: Monthly Total | K13: % of Total | L13: Annual Total
B14: Jan | C14: =COUNTA('✅ Monthly Checklist'!B5:B24) -> 15 | D14: =COUNTIF('✅ Monthly Checklist'!D5:D24,"Yes") -> 8 | E14: =C14-D14 -> 7 | F14: =SUM('✅ Monthly Checklist'!C5:C24) -> 3054.96 | G14: {=IFERROR(SUMPRODUCT(('✅ Monthly Checklist'!D5:D24="Yes")*('✅ Monthly Checklist'!C5:C24*1)),0)} -> 2320 | H14: =F14-G14 -> 734.96 | I14: Housing | J14: =SUMIF('📋 Bill List'!B3:B42,I14,'📋 Bill List'!C3:C42) -> 1500 | K14: =IF(J22>0,J14/J22,0) -> 0.49100479 | L14: =J14*12 -> 18000
B15: Feb | C15: =COUNTA('✅ Monthly Checklist'!B28:B47) -> 1 | D15: =COUNTIF('✅ Monthly Checklist'!D28:D47,"Yes") -> 0 | E15: =C15-D15 -> 1 | F15: =SUM('✅ Monthly Checklist'!C28:C47) -> 0 | G15: {=IFERROR(SUMPRODUCT(('✅ Monthly Checklist'!D28:D47="Yes")*('✅ Monthly Checklist'!C28:C47*1)),0)} -> 0 | H15: =F15-G15 -> 0 | I15: Utilities | J15: =SUMIF('📋 Bill List'!B3:B42,I15,'📋 Bill List'!C3:C42) -> 420 | K15: =IF(J22>0,J15/J22,0) -> 0.13748134 | L15: =J15*12 -> 5040
B16: Mar | C16: =COUNTA('✅ Monthly Checklist'!B51:B70) -> 1 | D16: =COUNTIF('✅ Monthly Checklist'!D51:D70,"Yes") -> 0 | E16: =C16-D16 -> 1 | F16: =SUM('✅ Monthly Checklist'!C51:C70) -> 0 | G16: {=IFERROR(SUMPRODUCT(('✅ Monthly Checklist'!D51:D70="Yes")*('✅ Monthly Checklist'!C51:C70*1)),0)} -> 0 | H16: =F16-G16 -> 0 | I16: Insurance | J16: =SUMIF('📋 Bill List'!B3:B42,I16,'📋 Bill List'!C3:C42) -> 425 | K16: =IF(J22>0,J16/J22,0) -> 0.13911802 | L16: =J16*12 -> 5100
B17: Apr | C17: =COUNTA('✅ Monthly Checklist'!B74:B93) -> 1 | D17: =COUNTIF('✅ Monthly Checklist'!D74:D93,"Yes") -> 0 | E17: =C17-D17 -> 1 | F17: =SUM('✅ Monthly Checklist'!C74:C93) -> 0 | G17: {=IFERROR(SUMPRODUCT(('✅ Monthly Checklist'!D74:D93="Yes")*('✅ Monthly Checklist'!C74:C93*1)),0)} -> 0 | H17: =F17-G17 -> 0 | I17: Transportation | J17: =SUMIF('📋 Bill List'!B3:B42,I17,'📋 Bill List'!C3:C42) -> 0 | K17: =IF(J22>0,J17/J22,0) -> 0 | L17: =J17*12 -> 0
B18: May | C18: =COUNTA('✅ Monthly Checklist'!B97:B116) -> 1 | D18: =COUNTIF('✅ Monthly Checklist'!D97:D116,"Yes") -> 0 | E18: =C18-D18 -> 1 | F18: =SUM('✅ Monthly Checklist'!C97:C116) -> 0 | G18: {=IFERROR(SUMPRODUCT(('✅ Monthly Checklist'!D97:D116="Yes")*('✅ Monthly Checklist'!C97:C116*1)),0)} -> 0 | H18: =F18-G18 -> 0 | I18: Subscriptions | J18: =SUMIF('📋 Bill List'!B3:B42,I18,'📋 Bill List'!C3:C42) -> 79.96 | K18: =IF(J22>0,J18/J22,0) -> 0.026173829 | L18: =J18*12 -> 959.52
B19: Jun | C19: =COUNTA('✅ Monthly Checklist'!B120:B139) -> 1 | D19: =COUNTIF('✅ Monthly Checklist'!D120:D139,"Yes") -> 0 | E19: =C19-D19 -> 1 | F19: =SUM('✅ Monthly Checklist'!C120:C139) -> 0 | G19: {=IFERROR(SUMPRODUCT(('✅ Monthly Checklist'!D120:D139="Yes")*('✅ Monthly Checklist'!C120:C139*1)),0)} -> 0 | H19: =F19-G19 -> 0 | I19: Loans | J19: =SUMIF('📋 Bill List'!B3:B42,I19,'📋 Bill List'!C3:C42) -> 630 | K19: =IF(J22>0,J19/J22,0) -> 0.20622201 | L19: =J19*12 -> 7560
B20: Jul | C20: =COUNTA('✅ Monthly Checklist'!B143:B162) -> 1 | D20: =COUNTIF('✅ Monthly Checklist'!D143:D162,"Yes") -> 0 | E20: =C20-D20 -> 1 | F20: =SUM('✅ Monthly Checklist'!C143:C162) -> 0 | G20: {=IFERROR(SUMPRODUCT(('✅ Monthly Checklist'!D143:D162="Yes")*('✅ Monthly Checklist'!C143:C162*1)),0)} -> 0 | H20: =F20-G20 -> 0 | I20: Medical | J20: =SUMIF('📋 Bill List'!B3:B42,I20,'📋 Bill List'!C3:C42) -> 0 | K20: =IF(J22>0,J20/J22,0) -> 0 | L20: =J20*12 -> 0
B21: Aug | C21: =COUNTA('✅ Monthly Checklist'!B166:B185) -> 1 | D21: =COUNTIF('✅ Monthly Checklist'!D166:D185,"Yes") -> 0 | E21: =C21-D21 -> 1 | F21: =SUM('✅ Monthly Checklist'!C166:C185) -> 0 | G21: {=IFERROR(SUMPRODUCT(('✅ Monthly Checklist'!D166:D185="Yes")*('✅ Monthly Checklist'!C166:C185*1)),0)} -> 0 | H21: =F21-G21 -> 0 | I21: Other | J21: =SUMIF('📋 Bill List'!B3:B42,I21,'📋 Bill List'!C3:C42) -> 0 | K21: =IF(J22>0,J21/J22,0) -> 0 | L21: =J21*12 -> 0
B22: Sep | C22: =COUNTA('✅ Monthly Checklist'!B189:B208) -> 1 | D22: =COUNTIF('✅ Monthly Checklist'!D189:D208,"Yes") -> 0 | E22: =C22-D22 -> 1 | F22: =SUM('✅ Monthly Checklist'!C189:C208) -> 0 | G22: {=IFERROR(SUMPRODUCT(('✅ Monthly Checklist'!D189:D208="Yes")*('✅ Monthly Checklist'!C189:C208*1)),0)} -> 0 | H22: =F22-G22 -> 0 | I22: TOTAL | J22: =SUM(J14:J21) -> 3054.96 | K22: 1 | L22: =SUM(L14:L21) -> 36659.52
B23: Oct | C23: =COUNTA('✅ Monthly Checklist'!B212:B231) -> 1 | D23: =COUNTIF('✅ Monthly Checklist'!D212:D231,"Yes") -> 0 | E23: =C23-D23 -> 1 | F23: =SUM('✅ Monthly Checklist'!C212:C231) -> 0 | G23: {=IFERROR(SUMPRODUCT(('✅ Monthly Checklist'!D212:D231="Yes")*('✅ Monthly Checklist'!C212:C231*1)),0)} -> 0 | H23: =F23-G23 -> 0
B24: Nov | C24: =COUNTA('✅ Monthly Checklist'!B235:B254) -> 1 | D24: =COUNTIF('✅ Monthly Checklist'!D235:D254,"Yes") -> 0 | E24: =C24-D24 -> 1 | F24: =SUM('✅ Monthly Checklist'!C235:C254) -> 0 | G24: {=IFERROR(SUMPRODUCT(('✅ Monthly Checklist'!D235:D254="Yes")*('✅ Monthly Checklist'!C235:C254*1)),0)} -> 0 | H24: =F24-G24 -> 0
B25: Dec | C25: =COUNTA('✅ Monthly Checklist'!B258:B277) -> 1 | D25: =COUNTIF('✅ Monthly Checklist'!D258:D277,"Yes") -> 0 | E25: =C25-D25 -> 1 | F25: =SUM('✅ Monthly Checklist'!C258:C277) -> 0 | G25: {=IFERROR(SUMPRODUCT(('✅ Monthly Checklist'!D258:D277="Yes")*('✅ Monthly Checklist'!C258:C277*1)),0)} -> 0 | H25: =F25-G25 -> 0
B26: TOTAL | C26: =SUM(C14:C25) -> 26 | D26: =SUM(D14:D25) -> 8 | E26: =SUM(E14:E25) -> 18 | F26: =SUM(F14:F25) -> 3054.96 | G26: =SUM(G14:G25) -> 2320 | H26: =SUM(H14:H25) -> 734.96

Sheet 📋 Bill List
A1: MASTER BILL LIST
A2: Bill Name | B2: Category | C2: Amount | D2: Due Date | E2: Frequency | F2: Payment Method | G2: Auto-Pay? | H2: Account # (Last 4) | I2: Website/App | J2: Notes
A3: Rent/Mortgage | B3: Housing | C3: 1500 | D3: 1st | E3: Monthly | F3: Bank Transfer | G3: Yes
A4: Electric | B4: Utilities | C4: 120 | D4: 15th | E4: Monthly | F4: Auto-Pay | G4: Yes
A5: Gas/Heating | B5: Utilities | C5: 80 | D5: 18th | E5: Monthly | F5: Auto-Pay | G5: Yes
A6: Water/Sewer | B6: Utilities | C6: 65 | D6: 20th | E6: Monthly | F6: Auto-Pay | G6: Yes
A7: Internet | B7: Utilities | C7: 70 | D7: 12th | E7: Monthly | F7: Credit Card | G7: Yes
A8: Phone | B8: Utilities | C8: 85 | D8: 22nd | E8: Monthly | F8: Auto-Pay | G8: Yes
A9: Car Insurance | B9: Insurance | C9: 150 | D9: 5th | E9: Monthly | F9: Bank Transfer | G9: Yes
A10: Health Insurance | B10: Insurance | C10: 250 | D10: 1st | E10: Monthly | F10: Payroll | G10: Yes
A11: Car Payment | B11: Loans | C11: 350 | D11: 10th | E11: Monthly | F11: Bank Transfer | G11: Yes
A12: Student Loan | B12: Loans | C12: 280 | D12: 25th | E12: Monthly | F12: Auto-Pay | G12: Yes
A13: Netflix | B13: Subscriptions | C13: 15.99 | D13: 8th | E13: Monthly | F13: Credit Card | G13: Yes
A14: Spotify | B14: Subscriptions | C14: 10.99 | D14: 14th | E14: Monthly | F14: Credit Card | G14: Yes
... A17: Cloud Storage | B17: Subscriptions | C17: 2.99 | D17: 20th | E17: Monthly | F17: Credit Card | G17: Yes
A42: TOTAL MONTHLY | C42: =SUM(C3:C41) -> 3054.96
A43: TOTAL ANNUAL (EST.) | C43: =SUMPRODUCT((E3:E41="Monthly")*(C3:C41)*12)+SUMPRODUCT((E3:E41="Quarterly")*(C3:C41)*4)+SUMPRODUCT((E3:E41="Semi-Annual")*(C3:C41)*2)+SUMPRODUCT((E3:E41="Annual")*(C3:C41)) -> 36659.52

Sheet ✅ Monthly Checklist
A1: MONTHLY PAYMENT CHECKLIST
A3: JANUARY
A4: Bill Name | B4: Due Date | C4: Amount | D4: Paid? | E4: Date Paid | F4: Confirmation # | G4: Notes
A5: Rent/Mortgage | B5: Jan 1st | C5: 1500 | D5: Yes | E5: 01/01
A6: Electric | B6: Jan 15th | C6: 120 | D6: Yes | E6: 01/15
A7: Gas/Heating | B7: Jan 18th | C7: 80 | D7: Yes | E7: 01/18
A8: Water/Sewer | B8: Jan 20th | C8: 65 | D8: Yes | E8: 01/20
A9: Internet | B9: Jan 12th | C9: 70 | D9: Yes | E9: 01/12
A10: Phone | B10: Jan 22nd | C10: 85 | D10: Yes | E10: 01/22
A11: Car Insurance | B11: Jan 5th | C11: 150 | D11: Yes | E11: 01/05
A12: Health Insurance | B12: Jan 1st | C12: 250 | D12: Yes | E12: 01/01
A13: Car Payment | B13: Jan 10th | C13: 350 | D13: No
A14: Student Loan | B14: Jan 25th | C14: 280 | D14: No
A15: Netflix | B15: Jan 8th | C15: 15.99 | D15: No
A16: Spotify | B16: Jan 14th | C16: 10.99 | D16: No
A17: Gym | B17: Jan 1st | C17: 49.99 | D17: No
A18: Renters Insurance | B18: Jan 1st | C18: 25 | D18: No
A19: Cloud Storage | B19: Jan 20th | C19: 2.99 | D19: No
A25: MONTHLY TOTAL | C25: =SUM(C5:C24) -> 3054.96 | E25: {=IFERROR(SUMPRODUCT((D5:D24="Yes")*(C5:C24*1)),0)} -> 2320
A27: FEBRUARY
A28: Bill Name | B28: Due Date | C28: Amount | D28: Paid? | E28: Date Paid | F28: Confirmation # | G28: Notes
A49: MONTHLY TOTAL | C49: =SUM(C29:C48) -> 0 | E49: {=IFERROR(SUMPRODUCT((D29:D48="Yes")*(C29:C48*1)),0)} -> 0
A51: MARCH
A52: Bill Name | B52: Due Date | C52: Amount | D52: Paid? | E52: Date Paid | F52: Confirmation # | G52: Notes
A73: MONTHLY TOTAL | C73: =SUM(C53:C72) -> 0 | E73: {=IFERROR(SUMPRODUCT((D53:D72="Yes")*(C53:C72*1)),0)} -> 0
A75: APRIL
A76: Bill Name | B76: Due Date | C76: Amount | D76: Paid? | E76: Date Paid | F76: Confirmation # | G76: Notes
A97: MONTHLY TOTAL | C97: =SUM(C77:C96) -> 0 | E97: {=IFERROR(SUMPRODUCT((D77:D96="Yes")*(C77:C96*1)),0)} -> 0
A99: MAY
A100: Bill Name | B100: Due Date | C100: Amount | D100: Paid? | E100: Date Paid | F100: Confirmation # | G100: Notes
A121: MONTHLY TOTAL | C121: =SUM(C101:C120) -> 0 | E121: {=IFERROR(SUMPRODUCT((D101:D120="Yes")*(C101:C120*1)),0)} -> 0
A123: JUNE
A124: Bill Name | B124: Due Date | C124: Amount | D124: Paid? | E124: Date Paid | F124: Confirmation # | G124: Notes
A145: MONTHLY TOTAL | C145: =SUM(C125:C144) -> 0 | E145: {=IFERROR(SUMPRODUCT((D125:D144="Yes")*(C125:C144*1)),0)} -> 0
A147: JULY
A148: Bill Name | B148: Due Date | C148: Amount | D148: Paid? | E148: Date Paid | F148: Confirmation # | G148: Notes
A169: MONTHLY TOTAL | C169: =SUM(C149:C168) -> 0 | E169: {=IFERROR(SUMPRODUCT((D149:D168="Yes")*(C149:C168*1)),0)} -> 0
A171: AUGUST
A172: Bill Name | B172: Due Date | C172: Amount | D172: Paid? | E172: Date Paid | F172: Confirmation # | G172: Notes
A193: MONTHLY TOTAL | C193: =SUM(C173:C192) -> 0 | E193: {=IFERROR(SUMPRODUCT((D173:D192="Yes")*(C173:C192*1)),0)} -> 0
...

Sheet 📱 Subscription Tracker
A1: SUBSCRIPTION TRACKER
A2: Service Name | B2: Category | C2: Monthly Cost | D2: Annual Cost | E2: Billing Cycle | F2: Last Renewed | G2: Next Renewal | H2: Still Using? | I2: Worth Keeping? | J2: Cancel Link | K2: Notes
A3: Netflix | B3: Entertainment | C3: 15.99 | D3: =C3*12 -> 191.88 | E3: Monthly | H3: Yes | I3: Yes
A4: Spotify | B4: Music | C4: 10.99 | D4: =C4*12 -> 131.88 | E4: Monthly | H4: Yes | I4: Yes
A5: Amazon Prime | B5: Shopping | C5: 14.99 | D5: =C5*12 -> 179.88 | E5: Monthly | H5: Yes | I5: Yes
A6: Gym Membership | B6: Health | C6: 49.99 | D6: =C6*12 -> 599.88 | E6: Monthly | H6: Yes | I6: Yes
A7: Cloud Storage | B7: Tech | C7: 2.99 | D7: =C7*12 -> 35.88 | E7: Monthly | H7: Yes | I7: Yes
A8: Streaming Service 2 | B8: Entertainment | C8: 12.99 | D8: =C8*12 -> 155.88 | E8: Monthly | H8: Yes | I8: No
A9: News Subscription | B9: Education | C9: 9.99 | D9: =C9*12 -> 119.88 | E9: Monthly | H9: No | I9: No
A10: Password Manager | B10: Tech | C10: 3.99 | D10: =C10*12 -> 47.88 | E10: Monthly | H10: Yes | I10: Yes
D11: =IF(C11<>"",C11*12,"")
D12: =IF(C12<>"",C12*12,"")
D13: =IF(C13<>"",C13*12,"")
D14: =IF(C14<>"",C14*12,"")
D15: =IF(C15<>"",C15*12,"")
D16: =IF(C16<>"",C16*12,"")
D17: =IF(C17<>"",C17*12,"")
D18: =IF(C18<>"",C18*12,"")
D19: =IF(C19<>"",C19*12,"")
D20: =IF(C20<>"",C20*12,"")
D21: =IF(C21<>"",C21*12,"")
C22: =SUM(C3:C21) -> 121.92 | D22: =IF(C22<>"",C22*12,"") -> 1463.04
A24: SUBSCRIPTION SUMMARY
A25: Total Monthly Subscription Cost | D25: =C22 -> 121.92
A26: Total Annual Subscription Cost | D26: =D22 -> 1463.04
A27: Potential Monthly Savings (Not Worth Keeping) | D27: =SUMPRODUCT((I3:I22="No")*(C3:C22)) -> 22.98
A28: Potential Annual Savings (Not Worth Keeping) | D28: {=SUMPRODUCT((I3:I22="No")*IF(ISNUMBER(D3:D22),D3:D22,0))} -> 275.76

Sheet 📅 Annual Calendar
A1: ANNUAL BILL CALENDAR
A2: Bird's eye view of all bills by month | Color-coded by category
A3: JANUARY | C3: FEBRUARY | E3: MARCH | G3: APRIL | I3: MAY | K3: JUNE | M3: JULY | O3: AUGUST | Q3: SEPTEMBER | S3: OCTOBER | U3: NOVEMBER | W3: DECEMBER
A4: Bill | B4: Amount | C4: Bill | D4: Amount | E4: Bill | F4: Amount | G4: Bill | H4: Amount | I4: Bill | J4: Amount | K4: Bill | L4: Amount | M4: Bill | N4: Amount | O4: Bill | P4: Amount | Q4: Bill | R4: Amount | S4: Bill | T4: Amount | U4: Bill | V4: Amount | W4: Bill | X4: Amount
A5: 1st - Rent/Mortgage | B5: 1500 | C5: 1st - Rent/Mortgage | D5: 1500 | E5: 1st - Rent/Mortgage | F5: 1500 | G5: 1st - Rent/Mortgage | H5: 1500 | I5: 1st - Rent/Mortgage | J5: 1500 | K5: 1st - Rent/Mortgage | L5: 1500 | M5: 1st - Rent/Mortgage | N5: 1500 | O5: 1st - Rent/Mortgage | P5: 1500 | Q5: 1st - Rent/Mortgage | R5: 1500 | S5: 1st - Rent/Mortgage | T5: 1500 | U5: 1st - Rent/Mortgage | V5: 1500 | W5: 1st - Rent/Mortgage | X5: 1500
A6: 15th - Electric | B6: 120 | C6: 15th - Electric | D6: 120 | E6: 15th - Electric | F6: 120 | G6: 15th - Electric | H6: 120 | I6: 15th - Electric | J6: 120 | K6: 15th - Electric | L6: 120 | M6: 15th - Electric | N6: 120 | O6: 15th - Electric | P6: 120 | Q6: 15th - Electric | R6: 120 | S6: 15th - Electric | T6: 120 | U6: 15th - Electric | V6: 120 | W6: 15th - Electric | X6: 120
A7: 18th - Gas/Heating | B7: 80 | C7: 18th - Gas/Heating | D7: 80 | E7: 18th - Gas/Heating | F7: 80 | G7: 18th - Gas/Heating | H7: 80 | I7: 18th - Gas/Heating | J7: 80 | K7: 18th - Gas/Heating | L7: 80 | M7: 18th - Gas/Heating | N7: 80 | O7: 18th - Gas/Heating | P7: 80 | Q7: 18th - Gas/Heating | R7: 80 | S7: 18th - Gas/Heating | T7: 80 | U7: 18th - Gas/Heating | V7: 80 | W7: 18th - Gas/Heating | X7: 80
A8: 20th - Water/Sewer | B8: 65 | C8: 20th - Water/Sewer | D8: 65 | E8: 20th - Water/Sewer | F8: 65 | G8: 20th - Water/Sewer | H8: 65 | I8: 20th - Water/Sewer | J8: 65 | K8: 20th - Water/Sewer | L8: 65 | M8: 20th - Water/Sewer | N8: 65 | O8: 20th - Water/Sewer | P8: 65 | Q8: 20th - Water/Sewer | R8: 65 | S8: 20th - Water/Sewer | T8: 65 | U8: 20th - Water/Sewer | V8: 65 | W8: 20th - Water/Sewer | X8: 65
A9: 12th - Internet | B9: 70 | C9: 12th - Internet | D9: 70 | E9: 12th - Internet | F9: 70 | G9: 12th - Internet | H9: 70 | I9: 12th - Internet | J9: 70 | K9: 12th - Internet | L9: 70 | M9: 12th - Internet | N9: 70 | O9: 12th - Internet | P9: 70 | Q9: 12th - Internet | R9: 70 | S9: 12th - Internet | T9: 70 | U9: 12th - Internet | V9: 70 | W9: 12th - Internet | X9: 70
A10: 22nd - Phone | B10: 85 | C10: 22nd - Phone | D10: 85 | E10: 22nd - Phone | F10: 85 | G10: 22nd - Phone | H10: 85 | I10: 22nd - Phone | J10: 85 | K10: 22nd - Phone | L10: 85 | M10: 22nd - Phone | N10: 85 | O10: 22nd - Phone | P10: 85 | Q10: 22nd - Phone | R10: 85 | S10: 22nd - Phone | T10: 85 | U10: 22nd - Phone | V10: 85 | W10: 22nd - Phone | X10: 85
A11: 5th - Car Insurance | B11: 150 | C11: 5th - Car Insurance | D11: 150 | E11: 5th - Car Insurance | F11: 150 | G11: 5th - Car Insurance | H11: 150 | I11: 5th - Car Insurance | J11: 150 | K11: 5th - Car Insurance | L11: 150 | M11: 5th - Car Insurance | N11: 150 | O11: 5th - Car Insurance | P11: 150 | Q11: 5th - Car Insurance | R11: 150 | S11: 5th - Car Insurance | T11: 150 | U11: 5th - Car Insurance | V11: 150 | W11: 5th - Car Insurance | X11: 150
A12: 1st - Health Insurance | B12: 250 | C12: 1st - Health Insurance | D12: 250 | E12: 1st - Health Insurance | F12: 250 | G12: 1st - Health Insurance | H12: 250 | I12: 1st - Health Insurance | J12: 250 | K12: 1st - Health Insurance | L12: 250 | M12: 1st - Health Insurance | N12: 250 | O12: 1st - Health Insurance | P12: 250 | Q12: 1st - Health Insurance | R12: 250 | S12: 1st - Health Insurance | T12: 250 | U12: 1st - Health Insurance | V12: 250 | W12: 1st - Health Insurance | X12: 250
A13: 10th - Car Payment | B13: 350 | C13: 10th - Car Payment | D13: 350 | E13: 10th - Car Payment | F13: 350 | G13: 10th - Car Payment | H13: 350 | I13: 10th - Car Payment | J13: 350 | K13: 10th - Car Payment | L13: 350 | M13: 10th - Car Payment | N13: 350 | O13: 10th - Car Payment | P13: 350 | Q13: 10th - Car Payment | R13: 350 | S13: 10th - Car Payment | T13: 350 | U13: 10th - Car Payment | V13: 350 | W13: 10th - Car Payment | X13: 350
A14: 25th - Student Loan | B14: 280 | C14: 25th - Student Loan | D14: 280 | E14: 25th - Student Loan | F14: 280 | G14: 25th - Student Loan | H14: 280 | I14: 25th - Student Loan | J14: 280 | K14: 25th - Student Loan | L14: 280 | M14: 25th - Student Loan | N14: 280 | O14: 25th - Student Loan | P14: 280 | Q14: 25th - Student Loan | R14: 280 | S14: 25th - Student Loan | T14: 280 | U14: 25th - Student Loan | V14: 280 | W14: 25th - Student Loan | X14: 280
A15: 8th - Netflix | B15: 15.99 | C15: 8th - Netflix | D15: 15.99 | E15: 8th - Netflix | F15: 15.99 | G15: 8th - Netflix | H15: 15.99 | I15: 8th - Netflix | J15: 15.99 | K15: 8th - Netflix | L15: 15.99 | M15: 8th - Netflix | N15: 15.99 | O15: 8th - Netflix | P15: 15.99 | Q15: 8th - Netflix | R15: 15.99 | S15: 8th - Netflix | T15: 15.99 | U15: 8th - Netflix | V15: 15.99 | W15: 8th - Netflix | X15: 15.99
A16: 14th - Spotify | B16: 10.99 | C16: 14th - Spotify | D16: 10.99 | E16: 14th - Spotify | F16: 10.99 | G16: 14th - Spotify | H16: 10.99 | I16: 14th - Spotify | J16: 10.99 | K16: 14th - Spotify | L16: 10.99 | M16: 14th - Spotify | N16: 10.99 | O16: 14th - Spotify | P16: 10.99 | Q16: 14th - Spotify | R16: 10.99 | S16: 14th - Spotify | T16: 10.99 | U16: 14th - Spotify | V16: 10.99 | W16: 14th - Spotify | X16: 10.99
... A19: 20th - Cloud Storage | B19: 2.99 | C19: 20th - Cloud Storage | D19: 2.99 | E19: 20th - Cloud Storage | F19: 2.99 | G19: 20th - Cloud Storage | H19: 2.99 | I19: 20th - Cloud Storage | J19: 2.99 | K19: 20th - Cloud Storage | L19: 2.99 | M19: 20th - Cloud Storage | N19: 2.99 | O19: 20th - Cloud Storage | P19: 2.99 | Q19: 20th - Cloud Storage | R19: 2.99 | S19: 20th - Cloud Storage | T19: 2.99 | U19: 20th - Cloud Storage | V19: 2.99 | W19: 20th - Cloud Storage | X19: 2.99
A25: TOTAL | B25: =SUM(B5:B24) -> 3054.96 | C25: TOTAL | D25: =SUM(D5:D24) -> 3054.96 | E25: TOTAL | F25: =SUM(F5:F24) -> 3054.96 | G25: TOTAL | H25: =SUM(H5:H24) -> 3054.96 | I25: TOTAL | J25: =SUM(J5:J24) -> 3054.96 | K25: TOTAL | L25: =SUM(L5:L24) -> 3054.96 | M25: TOTAL | N25: =SUM(N5:N24) -> 3054.96 | O25: TOTAL | P25: =SUM(P5:P24) -> 3054.96 | Q25: TOTAL | R25: =SUM(R5:R24) -> 3054.96 | S25: TOTAL | T25: =SUM(T5:T24) -> 3054.96 | U25: TOTAL | V25: =SUM(V5:V24) -> 3054.96 | W25: TOTAL | X25: =SUM(X5:X24) -> 3054.96
A27: CATEGORY LEGEND
A28: Housing | C28: Utilities | E28: Insurance | G28: Transportation
A29: Subscriptions | C29: Loans | E29: Medical | G29: Other

Sheet 📖 Instructions
A1: BILL ORGANIZER & PAYMENT TRACKER
A2: Setup Guide & Instructions
A4: Welcome to your Bill Organizer!
A5: This workbook helps you track every recurring bill, manage monthly payments, audit subscriptions, and plan ahead for the entire year. Follow the setup steps below to get started.
A7: SETUP STEPS
A8: 1. | B8: Step 1: Make a Copy
B9: Save a copy of this file so you always have a clean template. Name your working copy something like 'Bills-2026.xlsx'.
A10: 2. | B10: Step 2: Set Up Your Bill List
B11: Go to the 'Bill List' tab. Enter ALL your recurring bills - rent, utilities, insurance, loans, subscriptions, and anything you pay regularly. Fill in the amount, due date, frequency, and payment method for each.
A12: 3. | B12: Step 3: Set Up the Subscription Tracker
B13: Go to the 'Subscription Tracker' tab. Enter every subscription you pay for - streaming services, apps, memberships, software. Be honest about the 'Still Using?' and 'Worth Keeping?' columns.
A14: 4. | B14: Step 4: Use the Monthly Checklist
B15: Each month, go to the 'Monthly Checklist' tab and enter your bills for that month. Mark each as 'Yes' when paid, and record the date paid and confirmation number. This is your payment proof.
A16: 5. | B16: Step 5: Check the Dashboard
B17: The 'Dashboard' tab gives you an overview of your monthly bill situation - total bills, what's paid, what's remaining, and a category breakdown. Check it regularly.
A18: 6. | B18: Step 6: Review the Annual Calendar
B19: The 'Annual Calendar' tab shows all your bills across the entire year. Use it to plan ahead for expensive months and avoid surprises.
A20: 7. | B20: Step 7: Audit Subscriptions Quarterly
B21: Every 3 months, review the Subscription Tracker. Cancel anything you marked 'No' for 'Worth Keeping'. The potential savings section shows how much you could save.
A23: PRO TIPS
A24: TIP | B24: Set up auto-pay for every bill possible. This eliminates the risk of late fees and missed payments. Only keep manual payments for variable-amount bills.
A25: TIP | B25: Check the Subscription Tracker quarterly - cancel what you don't use. The average person wastes $30-50/month on forgotten subscriptions.
A26: TIP | B26: Use the Annual Calendar to plan ahead for expensive months. If you know March has high bills, start saving a little extra in January and February.
A27: TIP | B27: Keep confirmation numbers in the Monthly Checklist for disputes. If a payment ever goes missing or gets double-charged, you'll have proof.
A28: TIP | B28: Review your Dashboard at the start of each month. Know exactly what's due, what's already on auto-pay, and what needs manual attention.
A29: TIP | B29: Set calendar reminders 3 days before any bill that isn't on auto-pay. Prevention is easier than paying late fees.
A30: TIP | B30: If a bill amount changes, update BOTH the Bill List and the current month's checklist entry.
A32: FREQUENTLY ASKED QUESTIONS
A33: Q | B33: Q: How do I add a new bill?
A34: A | B34: A: Go to the 'Bill List' tab and enter the bill details in the next empty row. Then add it to the 'Monthly Checklist' for each month it's due.
A35: Q | B35: Q: What if a bill amount changes each month?
A36: A | B36: A: Put the average or typical amount in the Bill List. In the Monthly Checklist, enter the actual amount each month. The checklist total will be accurate.
A37: Q | B37: Q: How do I track quarterly or annual bills?
A38: A | B38: A: In the Bill List, set the Frequency to 'Quarterly' or 'Annual'. Then add the bill only to the specific months it's due in the Monthly Checklist.
A39: Q | B39: Q: Can I customize the categories?
A40: A | B40: A: Yes! The category dropdown can be updated. Right-click on a category cell, go to Data Validation, and edit the list.
A41: Q | B41: Q: What's the difference between the Bill List and Monthly Checklist?
A42: A | B42: A: The Bill List is your master reference of ALL recurring bills. The Monthly Checklist is where you track actual payments month by month - think of it as your payment diary.
A43: Q | B43: Q: How do I know if I'm overspending on subscriptions?
A44: A | B44: A: Check the Subscription Tracker summary at the bottom. Mark services you don't use or that aren't worth the cost - the 'Potential Savings' will show your waste.
...
